<robot name="my_car">

    <link name="foot_base_link">
        <visual>
            <origin xyz="0 0 0" rpy="0 0 0" />
            <geometry>
                <sphere radius="0.1" />
            </geometry>
            <material>
                <color rgba="10 10 50 1" /> 
            </material>            
        </visual>

    </link>

    <link name="base_link">
        <visual>
            <origin xyz="0 0 0.0" rpy="0 0 0"/>
            <geometry>
                <cylinder length="0.05" radius="0.5" />
            </geometry>
            <!-- <material>
                <color rgba="10 10 50 1" /> 
            </material>              -->
        </visual>
        <collision>
            <origin xyz="0 0 0.0" rpy="0 0 0"/>
            <geometry>
                <cylinder length="0.05" radius="0.5" />
            </geometry>
            <!-- <material>
                <color rgba="0.1 0.1 1.0 0.5" /> 
            </material> -->
        </collision>
        <inertial>
            <mass value="0.2"/>
            <inertia ixx="0.0125" ixy="0" ixz="0" iyy="0.0125" iyz="0" izz="0.025"/>
        </inertial>        
    </link>

    <joint name="base_to_foot" type="continuous">
        <parent link="foot_base_link" />
        <child link="base_link" />
        <origin xyz="0 0 0.5" />
        <!-- <axis xyz="1 1 1" /> -->
    </joint> 


    <link name="1_link">
        <visual>
            <origin xyz="0 0 0" rpy="0 1.57079 0"/>
            <geometry>
                <cylinder length="0.2" radius="0.25"/>
            </geometry>
            <!-- <material>
                <color rgba="10 10 50 0.8" /> 
            </material> -->
        </visual>
        <collision>
            <origin xyz="0 0 0.0" rpy="0 1.57079 0"/>
            <geometry>
                <cylinder length="0.2" radius="0.25"/>
            </geometry>
            <!-- <material>
                <color rgba="0.1 0.1 1.0 0.5" /> 
            </material> -->
        </collision>
        <inertial>
            <mass value="0.1"/>
            <inertia ixx="0.0018" ixy="0" ixz="0" iyy="0.0018" iyz="0" izz="0.03"/>
        </inertial>        
    </link> 

    <joint name="base_to_1" type="continuous">
        <parent link="base_link" />
        <child link="1_link" />
        <origin xyz="0.5 0 -0.25" />
        <axis xyz="1 0 0" />
    </joint>

    <link name="2_link">
        <visual>
            <origin xyz="0 0 0" rpy="0 1.57079 0" />
            <geometry>
                <cylinder length="0.2" radius="0.25" />
            </geometry>
            <!-- <material>
                <color rgba="10 10 50 0.8" /> 
            </material>             -->
        </visual>
        <collision>
            <origin xyz="0 0 0" rpy="0 1.57079 0" />
            <geometry>
                <cylinder length="0.2" radius="0.25" />
            </geometry>
            <!-- <material>
                <color rgba="0.1 0.1 1.0 0.5" /> 
            </material> -->
        </collision>
        <inertial>
            <mass value="0.1"/>
            <inertia ixx="0.0018" ixy="0" ixz="0" iyy="0.0018" iyz="0" izz="0.03"/>
        </inertial>        
    </link>

    <joint name="base_to_2" type="continuous">
        <parent link="base_link" />
        <child link="2_link" />
        <origin xyz="-0.5 0 -0.25" />
        <axis xyz="1 0 0" />
    </joint>    

</robot>